<?xml version="1.0" encoding="utf-8"?>
<!-- This URDF was automatically created by SolidWorks to URDF Exporter! Originally created by Stephen Brawner (brawner@gmail.com) 
     Commit Version: 1.6.0-1-g15f4949  Build Version: 1.6.7594.29634
     For more information, please see http://wiki.ros.org/sw_urdf_exporter -->
<robot
  name="ck_robot">
  <link
    name="base_link">
    <inertial>
      <origin
        xyz="-0.00383300691642972 0.182487946518564 -0.00270653843038907"
        rpy="0 0 0" />
      <mass
        value="60.1875042918917" />
      <inertia
        ixx="1.58272942356572"
        ixy="-1.00442188692039E-08"
        ixz="-6.13419343957741E-09"
        iyy="1.49216689626303"
        iyz="8.19101028357655E-06"
        izz="1.58271804885092" />
    </inertial>
    <visual>
      <origin
        xyz="0 0 0"
        rpy="0 0 0" />
      <geometry>
        <mesh
          filename="package://ck_robot/meshes/base_link.STL" />
      </geometry>
      <material
        name="">
        <color
          rgba="0.792156862745098 0.819607843137255 0.933333333333333 1" />
      </material>
    </visual>
    <collision>
      <origin
        xyz="0 0 0"
        rpy="0 0 0" />
      <geometry>
        <mesh
          filename="package://ck_robot/meshes/base_link.STL" />
      </geometry>
    </collision>
  </link>
  <link
    name="link_1">
    <inertial>
      <origin
        xyz="0.102809130750027 0.172949238194435 -0.0437090806062233"
        rpy="0 0 0" />
      <mass
        value="15.0344818329302" />
      <inertia
        ixx="0.361203035220433"
        ixy="-0.152719504927145"
        ixz="0.00578175214855801"
        iyy="0.646327534948922"
        iyz="0.0275012699513757"
        izz="0.643951501943441" />
    </inertial>
    <visual>
      <origin
        xyz="0 0 0"
        rpy="0 0 0" />
      <geometry>
        <mesh
          filename="package://ck_robot/meshes/link_1.STL" />
      </geometry>
      <material
        name="">
        <color
          rgba="1 1 1 1" />
      </material>
    </visual>
    <collision>
      <origin
        xyz="0 0 0"
        rpy="0 0 0" />
      <geometry>
        <mesh
          filename="package://ck_robot/meshes/link_1.STL" />
      </geometry>
    </collision>
  </link>
  <joint
    name="joint_1"
    type="continuous">
    <origin
      xyz="-0.00383300568916015 0.00270725046410668 0.340050258271999"
      rpy="1.5707963267949 0 -0.00605138749237428" />
    <parent
      link="base_link" />
    <child
      link="link_1" />
    <axis
      xyz="0 1 0" />
  </joint>
  <link
    name="link_2">
    <inertial>
      <origin
        xyz="3.4554120351693E-06 0.3026629257783 0.0958344910372751"
        rpy="0 0 0" />
      <mass
        value="13.7581112963571" />
      <inertia
        ixx="0.579000083558385"
        ixy="-8.26083819687151E-07"
        ixz="-2.5290843248637E-07"
        iyy="0.0576579722752854"
        iyz="-0.0273515955404406"
        izz="0.579286589232592" />
    </inertial>
    <visual>
      <origin
        xyz="0 0 0"
        rpy="0 0 0" />
      <geometry>
        <mesh
          filename="package://ck_robot/meshes/link_2.STL" />
      </geometry>
      <material
        name="">
        <color
          rgba="1 1 1 1" />
      </material>
    </visual>
    <collision>
      <origin
        xyz="0 0 0"
        rpy="0 0 0" />
      <geometry>
        <mesh
          filename="package://ck_robot/meshes/link_2.STL" />
      </geometry>
    </collision>
  </link>
  <joint
    name="joint_2"
    type="continuous">
    <origin
      xyz="0.285 0.279 0.0600067744860645"
      rpy="0 0 -1.53895939549721" />
    <parent
      link="link_1" />
    <child
      link="link_2" />
    <axis
      xyz="0 0 1" />
  </joint>
  <link
    name="link_3">
    <inertial>
      <origin
        xyz="-0.106987961252075 -0.0174869705654485 0.0776588400060666"
        rpy="0 0 0" />
      <mass
        value="13.0275184665504" />
      <inertia
        ixx="0.0627132545302885"
        ixy="-0.00841962883291324"
        ixz="0.0203139373595454"
        iyy="0.445601340238936"
        iyz="0.00436397624848644"
        izz="0.457027238244116" />
    </inertial>
    <visual>
      <origin
        xyz="0 0 0"
        rpy="0 0 0" />
      <geometry>
        <mesh
          filename="package://ck_robot/meshes/link_3.STL" />
      </geometry>
      <material
        name="">
        <color
          rgba="1 1 1 1" />
      </material>
    </visual>
    <collision>
      <origin
        xyz="0 0 0"
        rpy="0 0 0" />
      <geometry>
        <mesh
          filename="package://ck_robot/meshes/link_3.STL" />
      </geometry>
    </collision>
  </link>
  <joint
    name="joint_3"
    type="continuous">
    <origin
      xyz="0 0.680000000000004 0"
      rpy="3.14159265358979 0 -1.5859187836385" />
    <parent
      link="link_2" />
    <child
      link="link_3" />
    <axis
      xyz="0 0 1" />
  </joint>
  <link
    name="link_4">
    <inertial>
      <origin
        xyz="0.00674054248118688 0.109200955370313 0.000146060801288761"
        rpy="0 0 0" />
      <mass
        value="2.38079036358208" />
      <inertia
        ixx="0.0138352925270043"
        ixy="-0.00127243699344472"
        ixz="-7.82507607581127E-06"
        iyy="0.00431377534403387"
        iyz="1.88075396199067E-06"
        izz="0.0140397552963143" />
    </inertial>
    <visual>
      <origin
        xyz="0 0 0"
        rpy="0 0 0" />
      <geometry>
        <mesh
          filename="package://ck_robot/meshes/link_4.STL" />
      </geometry>
      <material
        name="">
        <color
          rgba="1 1 1 1" />
      </material>
    </visual>
    <collision>
      <origin
        xyz="0 0 0"
        rpy="0 0 0" />
      <geometry>
        <mesh
          filename="package://ck_robot/meshes/link_4.STL" />
      </geometry>
    </collision>
  </link>
  <joint
    name="joint_4"
    type="continuous">
    <origin
      xyz="-0.473242791686348 -0.0224999999999999 0.0930067744860649"
      rpy="3.14159265358978 -1.48381066723595 -1.57079632679489" />
    <parent
      link="link_3" />
    <child
      link="link_4" />
    <axis
      xyz="0 1 0" />
  </joint>
  <link
    name="link_5">
    <inertial>
      <origin
        xyz="-0.00237320370358729 4.02274061028773E-06 0.0564415415907327"
        rpy="0 0 0" />
      <mass
        value="1.79281371541231" />
      <inertia
        ixx="0.00559744708984224"
        ixy="-1.28486996486035E-07"
        ixz="0.000253091080705458"
        iyy="0.0113978041121914"
        iyz="-4.93958641329883E-07"
        izz="0.00867632894913552" />
    </inertial>
    <visual>
      <origin
        xyz="0 0 0"
        rpy="0 0 0" />
      <geometry>
        <mesh
          filename="package://ck_robot/meshes/link_5.STL" />
      </geometry>
      <material
        name="">
        <color
          rgba="1 1 1 1" />
      </material>
    </visual>
    <collision>
      <origin
        xyz="0 0 0"
        rpy="0 0 0" />
      <geometry>
        <mesh
          filename="package://ck_robot/meshes/link_5.STL" />
      </geometry>
    </collision>
  </link>
  <joint
    name="joint_5"
    type="continuous">
    <origin
      xyz="0 0.193257208313652 0"
      rpy="-1.64879993389354 0 0" />
    <parent
      link="link_4" />
    <child
      link="link_5" />
    <axis
      xyz="1 0 0" />
  </joint>
  <link
    name="link_6">
    <inertial>
      <origin
        xyz="8.57589364711142E-06 -0.0809075068589164 0.163038732849474"
        rpy="0 0 0" />
      <mass
        value="24.8877693978715" />
      <inertia
        ixx="0.638943130648103"
        ixy="7.13591888199666E-05"
        ixz="-4.02412291479427E-07"
        iyy="0.314906336978164"
        iyz="0.00124981910517799"
        izz="0.894637019266292" />
    </inertial>
    <visual>
      <origin
        xyz="0 0 0"
        rpy="0 0 0" />
      <geometry>
        <mesh
          filename="package://ck_robot/meshes/link_6.STL" />
      </geometry>
      <material
        name="">
        <color
          rgba="0.792156862745098 0.819607843137255 0.933333333333333 1" />
      </material>
    </visual>
    <collision>
      <origin
        xyz="0 0 0"
        rpy="0 0 0" />
      <geometry>
        <mesh
          filename="package://ck_robot/meshes/link_6.STL" />
      </geometry>
    </collision>
  </link>
  <joint
    name="joint_6"
    type="continuous">
    <origin
      xyz="-0.00299999999999894 0 0.102405955386691"
      rpy="0 0 -0.889895608487581" />
    <parent
      link="link_5" />
    <child
      link="link_6" />
    <axis
      xyz="0 0 1" />
  </joint>
</robot>