<?xml version="1.0" encoding="utf-8"?>
<!-- This URDF was automatically created by SolidWorks to URDF Exporter! Originally created by Stephen Brawner (brawner@gmail.com) 
     Commit Version: 1.6.0-1-g15f4949  Build Version: 1.6.7594.29634
     For more information, please see http://wiki.ros.org/sw_urdf_exporter -->
<robot
  name="ck_robot">
  <link name="world" />
  <link
    name="base_link">
    <inertial>
      <origin
        xyz="0.268464969990104 0.284520791548056 0.59851966368383"
        rpy="0 0 0" />
      <mass
        value="60.1875042918917" />
      <inertia
        ixx="1.58272942356572"
        ixy="-1.00442193082991E-08"
        ixz="-6.13419327373049E-09"
        iyy="1.49216689626303"
        iyz="8.19101028288463E-06"
        izz="1.58271804885092" />
    </inertial>
    <visual>
      <origin
        xyz="0 0 0"
        rpy="0 0 0" />
      <geometry>
        <mesh
          filename="package://ck_robot/meshes/base_link.STL" />
      </geometry>
      <material
        name="">
        <color
          rgba="0.792156862745098 0.819607843137255 0.933333333333333 1" />
      </material>
    </visual>
    <collision>
      <origin
        xyz="0 0 0"
        rpy="0 0 0" />
      <geometry>
        <mesh
          filename="package://ck_robot/meshes/base_link.STL" />
      </geometry>
    </collision>
  </link>
  <link
    name="link_1">
    <inertial>
      <origin
        xyz="0.10280930500268 0.172949537137502 -0.0437085356954771"
        rpy="0 0 0" />
      <mass
        value="1" />
      <inertia
        ixx="0.361208774715564"
        ixy="-0.152719163095036"
        ixz="0.00577624624249581"
        iyy="0.646329104489432"
        iyz="0.0274979066592256"
        izz="0.643947644736266" />
    </inertial>
    <visual>
      <origin
        xyz="0 0 0"
        rpy="0 0 0" />
      <geometry>
        <mesh
          filename="package://ck_robot/meshes/link_1.STL" />
      </geometry>
      <material
        name="">
        <color
          rgba="0.792156862745098 0.819607843137255 0.933333333333333 1" />
      </material>
    </visual>
    <collision>
      <origin
        xyz="0 0 0"
        rpy="0 0 0" />
      <geometry>
        <mesh
          filename="package://ck_robot/meshes/link_1.STL" />
      </geometry>
    </collision>
  </link>
  <joint name="world_to_base_link" type="fixed">
    <parent link="world" />
    <child link="base_link" />
  </joint>
  <joint
    name="joint_1"
    type="continuous">
    <origin
      xyz="0.268464971217371 -0.598518951650115 0.442083103301491"
      rpy="1.5707963267949 0 0.144460400809996" />
    <parent
      link="base_link" />
    <child
      link="link_1" />
    <axis
      xyz="0 1 0" />
  </joint>
  <link
    name="link_2">
    <inertial>
      <origin
        xyz="0.000189695035715642 0.303434216398242 0.155090259860337"
        rpy="0 0 0" />
      <mass
        value="1" />
      <inertia
        ixx="0.593276686471504"
        ixy="-0.000669754979847111"
        ixz="0.000213393474780362"
        iyy="0.0591609394583497"
        iyz="-0.0259775958519965"
        izz="0.59310381188485" />
    </inertial>
    <visual>
      <origin
        xyz="0 0 0"
        rpy="0 0 0" />
      <geometry>
        <mesh
          filename="package://ck_robot/meshes/link_2.STL" />
      </geometry>
      <material
        name="">
        <color
          rgba="0.792156862745098 0.819607843137255 0.933333333333333 1" />
      </material>
    </visual>
    <collision>
      <origin
        xyz="0 0 0"
        rpy="0 0 0" />
      <geometry>
        <mesh
          filename="package://ck_robot/meshes/link_2.STL" />
      </geometry>
    </collision>
  </link>
  <joint
    name="joint_2"
    type="continuous">
    <origin
      xyz="0.285 0.279 0"
      rpy="0 0 -1.27141640789434" />
    <parent
      link="link_1" />
    <child
      link="link_2" />
    <axis
      xyz="0 0 1" />
  </joint>
  <link
    name="link_3">
    <inertial>
      <origin
        xyz="-0.106989348552819 -0.0174835771333657 0.017651513701905"
        rpy="0 0 0" />
      <mass
        value="1" />
      <inertia
        ixx="0.0627293128565049"
        ixy="-0.0084283421700578"
        ixz="0.0203383321733268"
        iyy="0.445734573968538"
        iyz="0.00436690377630759"
        izz="0.457163524633178" />
    </inertial>
    <visual>
      <origin
        xyz="0 0 0"
        rpy="0 0 0" />
      <geometry>
        <mesh
          filename="package://ck_robot/meshes/link_3.STL" />
      </geometry>
      <material
        name="">
        <color
          rgba="0.792156862745098 0.819607843137255 0.933333333333333 1" />
      </material>
    </visual>
    <collision>
      <origin
        xyz="0 0 0"
        rpy="0 0 0" />
      <geometry>
        <mesh
          filename="package://ck_robot/meshes/link_3.STL" />
      </geometry>
    </collision>
  </link>
  <joint
    name="joint_3"
    type="continuous">
    <origin
      xyz="0 0.67999999999999 0"
      rpy="-3.14159265358979 0 -0.313045625626455" />
    <parent
      link="link_2" />
    <child
      link="link_3" />
    <axis
      xyz="0 0 1" />
  </joint>
  <link
    name="link_4">
    <inertial>
      <origin
        xyz="0.00674065478440106 0.108276652100493 0.000146088737235539"
        rpy="0 0 0" />
      <mass
        value="1" />
      <inertia
        ixx="0.0138352619261862"
        ixy="-0.00127244271994891"
        ixz="-7.82632002535892E-06"
        iyy="0.00431376770209576"
        iyz="1.87534580523264E-06"
        izz="0.0140397247314502" />
    </inertial>
    <visual>
      <origin
        xyz="0 0 0"
        rpy="0 0 0" />
      <geometry>
        <mesh
          filename="package://ck_robot/meshes/link_4.STL" />
      </geometry>
      <material
        name="">
        <color
          rgba="0.792156862745098 0.819607843137255 0.933333333333333 1" />
      </material>
    </visual>
    <collision>
      <origin
        xyz="0 0 0"
        rpy="0 0 0" />
      <geometry>
        <mesh
          filename="package://ck_robot/meshes/link_4.STL" />
      </geometry>
    </collision>
  </link>
  <joint
    name="joint_4"
    type="continuous">
    <origin
      xyz="-0.474166946244357 -0.022499999999998 0.0329999999999995"
      rpy="0 0.956127472462032 1.5707963267949" />
    <parent
      link="link_3" />
    <child
      link="link_4" />
    <axis
      xyz="0 1 0" />
  </joint>
  <link
    name="link_5">
    <inertial>
      <origin
        xyz="-0.0153730128815858 3.63685714777073E-06 0.0564414779216935"
        rpy="0 0 0" />
      <mass
        value="1" />
      <inertia
        ixx="0.00559747896590421"
        ixy="-1.9326688324012E-07"
        ixz="0.000253093583976348"
        iyy="0.0113977417293985"
        iyz="-5.42342142822669E-07"
        izz="0.00867630419925224" />
    </inertial>
    <visual>
      <origin
        xyz="0 0 0"
        rpy="0 0 0" />
      <geometry>
        <mesh
          filename="package://ck_robot/meshes/link_5.STL" />
      </geometry>
      <material
        name="">
        <color
          rgba="0.792156862745098 0.819607843137255 0.933333333333333 1" />
      </material>
    </visual>
    <collision>
      <origin
        xyz="0 0 0"
        rpy="0 0 0" />
      <geometry>
        <mesh
          filename="package://ck_robot/meshes/link_5.STL" />
      </geometry>
    </collision>
  </link>
  <joint
    name="joint_5"
    type="continuous">
    <origin
      xyz="0 0.192333053755625 0"
      rpy="2.51840109391516 0 3.14159265358979" />
    <parent
      link="link_4" />
    <child
      link="link_5" />
    <axis
      xyz="1 0 0" />
  </joint>
  <link
    name="link_6">
    <inertial>
      <origin
        xyz="8.56454542169649E-06 -0.0809075419567876 0.265444706436671"
        rpy="0 0 0" />
      <mass
        value="1" />
      <inertia
        ixx="0.638941947594122"
        ixy="7.18496179886287E-05"
        ixz="-8.54297844271601E-08"
        iyy="0.314905899619827"
        iyz="0.00125056364890488"
        izz="0.894635702009243" />
    </inertial>
    <visual>
      <origin
        xyz="0 0 0"
        rpy="0 0 0" />
      <geometry>
        <mesh
          filename="package://ck_robot/meshes/link_6.STL" />
      </geometry>
      <material
        name="">
        <color
          rgba="1 1 1 1" />
      </material>
    </visual>
    <collision>
      <origin
        xyz="0 0 0"
        rpy="0 0 0" />
      <geometry>
        <mesh
          filename="package://ck_robot/meshes/link_6.STL" />
      </geometry>
    </collision>
  </link>
  <joint
    name="joint_6"
    type="continuous">
    <origin
      xyz="-0.0159999999999946 0 0"
      rpy="0 0 0.232084976469764" />
    <parent
      link="link_5" />
    <child
      link="link_6" />
    <axis
      xyz="0 0 1" />
  </joint>

  <transmission name="trans_1">
    <type>transmission_interface/SimpleTransmission</type>
    <joint name="joint_1">
      <hardwareInterface>hardware_interface/VelocityJointInterface</hardwareInterface>
    </joint>
    <actuator name="motor_1">
      <mechanicalReduction>50</mechanicalReduction>
      <hardwareInterface>hardware_interface/VelocityJointInterface</hardwareInterface>
    </actuator>
 </transmission>

  <transmission name="trans_2">
    <type>transmission_interface/SimpleTransmission</type>
    <joint name="joint_2">
      <hardwareInterface>hardware_interface/VelocityJointInterface</hardwareInterface>
    </joint>
    <actuator name="motor_2">
      <mechanicalReduction>50</mechanicalReduction>
      <hardwareInterface>hardware_interface/VelocityJointInterface</hardwareInterface>
    </actuator>
 </transmission>

  <transmission name="trans_3">
    <type>transmission_interface/SimpleTransmission</type>
    <joint name="joint_3">
      <hardwareInterface>hardware_interface/VelocityJointInterface</hardwareInterface>
    </joint>
    <actuator name="motor_3">
      <mechanicalReduction>50</mechanicalReduction>
      <hardwareInterface>hardware_interface/VelocityJointInterface</hardwareInterface>
    </actuator>
 </transmission>

  <transmission name="trans_4">
    <type>transmission_interface/SimpleTransmission</type>
    <joint name="joint_4">
      <hardwareInterface>hardware_interface/VelocityJointInterface</hardwareInterface>
    </joint>
    <actuator name="motor_4">
      <mechanicalReduction>50</mechanicalReduction>
      <hardwareInterface>hardware_interface/VelocityJointInterface</hardwareInterface>
    </actuator>
 </transmission>

  <transmission name="trans_5">
    <type>transmission_interface/SimpleTransmission</type>
    <joint name="joint_5">
      <hardwareInterface>hardware_interface/VelocityJointInterface</hardwareInterface>
    </joint>
    <actuator name="motor_5">
      <mechanicalReduction>50</mechanicalReduction>
      <hardwareInterface>hardware_interface/VelocityJointInterface</hardwareInterface>
    </actuator>
 </transmission>

  <transmission name="trans_6">
    <type>transmission_interface/SimpleTransmission</type>
    <joint name="joint_6">
      <hardwareInterface>hardware_interface/VelocityJointInterface</hardwareInterface>
    </joint>
    <actuator name="motor_6">
      <mechanicalReduction>50</mechanicalReduction>
      <hardwareInterface>hardware_interface/VelocityJointInterface</hardwareInterface>
    </actuator>
 </transmission>

 <gazebo reference="base_link">
  <gravity>0</gravity>
 </gazebo>
 <gazebo reference="link_1">
  <gravity>0</gravity>
 </gazebo>
 <gazebo reference="link_2">
  <gravity>0</gravity>
 </gazebo>
 <gazebo reference="link_3">
  <gravity>0</gravity>
 </gazebo>
 <gazebo reference="link_4">
  <gravity>0</gravity>
 </gazebo>
 <gazebo reference="link_5">
  <gravity>0</gravity>
 </gazebo>
 <gazebo reference="link_6">
  <gravity>0</gravity>
 </gazebo>

</robot>
